Workbook
Name _Toc110165884: ' Amendment History'!$B$6
Name _Toc110165884: 'Test Cases Summary'!$B$5

Sheet Test Cases Summary
B2: Project Test Summary
B3: Project Title | C3: =TC_Common!C6:E6 -> MTLD-CM Matching Tool
B4: Base Template ID: | C4: DP-TCD-TMP-V2.1
B5: Test Cases Status Summary for Project
B6: Execution Status | C6: Total Test Cases | D6: Total Test Cases Executed | E6: Pass | F6: Fail | G6: Not Tested
C7: =SUM(C22,C35,C48,C61,C74,C87,C100,C113,C126,C139,C152,C165,C178,C191,C204,C217,C230,C243,C256,C269) -> 86 | D7: =SUM(D22,D35,D48,D61,D74,D87,D100,D113,D126,D139,D152,D165,D178,D191,D204,D217,D230,D243,D256,D269) -> 0 | E7: =SUM(E22,E35,E48,E61,E74,E87,E100,E113,E126,E139,E152,E165,E178,E191,E204,E217,E230,E243,E256,E269) -> 0 | F7: =SUM(F22,F35,F48,F61,F74,F87,F100,F113,F126,F139,F152,F165,F178,F191,F204,F217,F230,F243,F256,F269) -> 0 | G7: =SUM(G22,G35,G48,G61,G74,G87,G100,G113,G126,G139,G152,G165,G178,G191,G204,G217,G230,G243,G256,G269) -> 0 | J7: I
B10: Module-wise Test Execution Summary | I10: Module-wise Graphical Test Execution Summary
B11: Module Name | C11: Iterations | D11: Total Test Cases Executed | E11: Pass | F11: Fail | G11: Not Tested
B12: =TC_Common!C$7 -> TC_Common | C12: Iteration - 1 | D12: =SUM(COUNTIF(TC_Common!L$10:L$2264,"Pass")+COUNTIF(TC_Common!L$10:L$2264,"Fail")+COUNTIF(TC_Common!L$10:L$2264,"Not Tested")) -> 0 | E12: =COUNTIF(TC_Common!L$10:L$2264, "Pass") -> 0 | F12: =COUNTIF(TC_Common!L$10:L$2264, "Fail") -> 0 | G12: =COUNTIF(TC_Common!L$10:L$2264, "Not Tested") -> 0 | H12: J
C13: Iteration - 2 | D13: =SUM(COUNTIF(TC_Common!R$10:R$2264,"Pass")+COUNTIF(TC_Common!R$10:R$2264,"Fail")+COUNTIF(TC_Common!R$10:R$2264,"Not Tested")) -> 0 | E13: =COUNTIF(TC_Common!R$10:R$2264, "Pass") -> 0 | F13: =COUNTIF(TC_Common!R$10:R$2264, "Fail") -> 0 | G13: =COUNTIF(TC_Common!R$10:R$2264, "Not Tested") -> 0 | H13: P
C14: Iteration - 3 | D14: =SUM(COUNTIF(TC_Common!X$10:X$2264,"Pass")+COUNTIF(TC_Common!X$10:X$2264,"Fail")+COUNTIF(TC_Common!X$10:X$2264,"Not Tested")) -> 0 | E14: =COUNTIF(TC_Common!X$10:X$2264, "Pass") -> 0 | F14: =COUNTIF(TC_Common!X$10:X$2264, "Fail") -> 0 | G14: =COUNTIF(TC_Common!X$10:X$2264, "Not Tested") -> 0 | H14: V
C15: Iteration - 4 | D15: =SUM(COUNTIF(TC_Common!AD$10:AD$2264,"Pass")+COUNTIF(TC_Common!AD$10:AD$2264,"Fail")+COUNTIF(TC_Common!AD$10:AD$2264,"Not Tested")) -> 0 | E15: =COUNTIF(TC_Common!AD$10:AD$2264, "Pass") -> 0 | F15: =COUNTIF(TC_Common!AD$10:AD$2264, "Fail") -> 0 | G15: =COUNTIF(TC_Common!AD$10:AD$2264, "Not Tested") -> 0 | H15: AB
C16: Iteration - 5 | D16: =SUM(COUNTIF(TC_Common!AJ$10:AJ$2264,"Pass")+COUNTIF(TC_Common!AJ$10:AJ$2264,"Fail")+COUNTIF(TC_Common!AJ$10:AJ$2264,"Not Tested")) -> 0 | E16: =COUNTIF(TC_Common!AJ$10:AJ$2264, "Pass") -> 0 | F16: =COUNTIF(TC_Common!AJ$10:AJ$2264, "Fail") -> 0 | G16: =COUNTIF(TC_Common!AJ$10:AJ$2264, "Not Tested") -> 0 | H16: AH
C17: Iteration - 6 | D17: =SUM(COUNTIF(TC_Common!AP$10:AP$2264,"Pass")+COUNTIF(TC_Common!AP$10:AP$2264,"Fail")+COUNTIF(TC_Common!AP$10:AP$2264,"Not Tested")) -> 0 | E17: =COUNTIF(TC_Common!AP$10:AP$2264, "Pass") -> 0 | F17: =COUNTIF(TC_Common!AP$10:AP$2264, "Fail") -> 0 | G17: =COUNTIF(TC_Common!AP$10:AP$2264, "Not Tested") -> 0 | H17: AN
C18: Iteration - 7 | D18: =SUM(COUNTIF(TC_Common!AV$10:AV$2264,"Pass")+COUNTIF(TC_Common!AV$10:AV$2264,"Fail")+COUNTIF(TC_Common!AV$10:AV$2264,"Not Tested")) -> 0 | E18: =COUNTIF(TC_Common!AV$10:AV$2264, "Pass") -> 0 | F18: =COUNTIF(TC_Common!AV$10:AV$2264, "Fail") -> 0 | G18: =COUNTIF(TC_Common!AV$10:AV$2264, "Not Tested") -> 0 | H18: AT
C19: Iteration - 8 | D19: =SUM(COUNTIF(TC_Common!BB$10:BB$2264,"Pass")+COUNTIF(TC_Common!BB$10:BB$2264,"Fail")+COUNTIF(TC_Common!BB$10:BB$2264,"Not Tested")) -> 0 | E19: =COUNTIF(TC_Common!BB$10:BB$2264, "Pass") -> 0 | F19: =COUNTIF(TC_Common!BB$10:BB$2264, "Fail") -> 0 | G19: =COUNTIF(TC_Common!BB$10:BB$2264, "Not Tested") -> 0 | H19: AZ
C20: Iteration - 8 | D20: =SUM(COUNTIF(TC_Common!BH$10:BH$2264,"Pass")+COUNTIF(TC_Common!BH$10:BH$2264,"Fail")+COUNTIF(TC_Common!BH$10:BH$2264,"Not Tested")) -> 0 | E20: =COUNTIF(TC_Common!BH$10:BH$2264, "Pass") -> 0 | F20: =COUNTIF(TC_Common!BH$10:BH$2264, "Fail") -> 0 | G20: =COUNTIF(TC_Common!BH$10:BH$2264, "Not Tested") -> 0 | H20: BF
C21: Iteration - 10 | D21: =SUM(COUNTIF(TC_Common!BN$10:BN$2264,"Pass")+COUNTIF(TC_Common!BN$10:BN$2264,"Fail")+COUNTIF(TC_Common!BN$10:BN$2264,"Not Tested")) -> 0 | E21: =COUNTIF(TC_Common!BN$10:BN$2264, "Pass") -> 0 | F21: =COUNTIF(TC_Common!BN$10:BN$2264, "Fail") -> 0 | G21: =COUNTIF(TC_Common!BN$10:BN$2264, "Not Tested") -> 0 | H21: BL
B22: Total Test Cases= | C22: =COUNTA(TC_Common!E$10:E$2264) -> 11 | D22: =SUMIF(D12:D21,">=1")/IF(COUNTIF(D12:D21,">=1")=0,COUNTA(D12:D21),COUNTIF(D12:D21,">=1")) -> 0 | E22: =SUMIF(E12:E21,">=1")/IF(COUNTIF(E12:E21,">=1")=0,COUNTA(E12:E21),COUNTIF(D12:D21,">=1")) -> 0 | F22: =SUMIF(F12:F21,">=1")/IF(COUNTIF(F12:F21,">=1")=0,COUNTA(F12:F21),COUNTIF(D12:D21,">=1")) -> 0 | G22: =SUMIF(G12:G21,">=1")/IF(COUNTIF(G12:G21,">=1")=0,COUNTA(G12:G21),COUNTIF(D12:D21,">=1")) -> 0
B24: Module Name | C24: Iterations | D24: Total Test Cases Executed | E24: Pass | F24: Fail | G24: Not Tested
B25: =#REF! -> #REF! | C25: Iteration - 1 | D25: =SUM(COUNTIF(#REF!,"Pass")+COUNTIF(#REF!,"Fail")+COUNTIF(#REF!,"Not Tested")) -> #REF! | E25: =COUNTIF(#REF!, "Pass") -> #REF! | F25: =COUNTIF(#REF!, "Fail") -> #REF! | G25: =COUNTIF(#REF!, "Not Tested") -> #REF!
C26: Iteration - 2 | D26: =SUM(COUNTIF(#REF!,"Pass")+COUNTIF(#REF!,"Fail")+COUNTIF(#REF!,"Not Tested")) -> #REF! | E26: =COUNTIF(#REF!, "Pass") -> #REF! | F26: =COUNTIF(#REF!, "Fail") -> #REF! | G26: =COUNTIF(#REF!, "Not Tested") -> #REF!
C27: Iteration - 3 | D27: =SUM(COUNTIF(#REF!,"Pass")+COUNTIF(#REF!,"Fail")+COUNTIF(#REF!,"Not Tested")) -> #REF! | E27: =COUNTIF(#REF!, "Pass") -> #REF! | F27: =COUNTIF(#REF!, "Fail") -> #REF! | G27: =COUNTIF(#REF!, "Not Tested") -> #REF!
C28: Iteration - 4 | D28: =SUM(COUNTIF(#REF!,"Pass")+COUNTIF(#REF!,"Fail")+COUNTIF(#REF!,"Not Tested")) -> #REF! | E28: =COUNTIF(#REF!, "Pass") -> #REF! | F28: =COUNTIF(#REF!, "Fail") -> #REF! | G28: =COUNTIF(#REF!, "Not Tested") -> #REF!
C29: Iteration - 5 | D29: =SUM(COUNTIF(#REF!,"Pass")+COUNTIF(#REF!,"Fail")+COUNTIF(#REF!,"Not Tested")) -> #REF! | E29: =COUNTIF(#REF!, "Pass") -> #REF! | F29: =COUNTIF(#REF!, "Fail") -> #REF! | G29: =COUNTIF(#REF!, "Not Tested") -> #REF!
C30: Iteration - 6 | D30: =SUM(COUNTIF(#REF!,"Pass")+COUNTIF(#REF!,"Fail")+COUNTIF(#REF!,"Not Tested")) -> #REF! | E30: =COUNTIF(#REF!, "Pass") -> #REF! | F30: =COUNTIF(#REF!, "Fail") -> #REF! | G30: =COUNTIF(#REF!, "Not Tested") -> #REF!
C31: Iteration - 7 | D31: =SUM(COUNTIF(#REF!,"Pass")+COUNTIF(#REF!,"Fail")+COUNTIF(#REF!,"Not Tested")) -> #REF! | E31: =COUNTIF(#REF!, "Pass") -> #REF! | F31: =COUNTIF(#REF!, "Fail") -> #REF! | G31: =COUNTIF(#REF!, "Not Tested") -> #REF!
C32: Iteration - 8 | D32: =SUM(COUNTIF(#REF!,"Pass")+COUNTIF(#REF!,"Fail")+COUNTIF(#REF!,"Not Tested")) -> #REF! | E32: =COUNTIF(#REF!, "Pass") -> #REF! | F32: =COUNTIF(#REF!, "Fail") -> #REF! | G32: =COUNTIF(#REF!, "Not Tested") -> #REF!
C33: Iteration - 9 | D33: =SUM(COUNTIF(#REF!,"Pass")+COUNTIF(#REF!,"Fail")+COUNTIF(#REF!,"Not Tested")) -> #REF! | E33: =COUNTIF(#REF!, "Pass") -> #REF! | F33: =COUNTIF(#REF!, "Fail") -> #REF! | G33: =COUNTIF(#REF!, "Not Tested") -> #REF!
C34: Iteration - 10 | D34: =SUM(COUNTIF(#REF!,"Pass")+COUNTIF(#REF!,"Fail")+COUNTIF(#REF!,"Not Tested")) -> #REF! | E34: =COUNTIF(#REF!, "Pass") -> #REF! | F34: =COUNTIF(#REF!, "Fail") -> #REF! | G34: =COUNTIF(#REF!, "Not Tested") -> #REF!
B35: Total Test Cases= | C35: =COUNTA(#REF!) -> 1 | D35: =SUMIF(D25:D34,">=1")/IF(COUNTIF(D25:D34,">=1")=0,COUNTA(D25:D34),COUNTIF(D25:D34,">=1")) -> 0 | E35: =SUMIF(E25:E34,">=1")/IF(COUNTIF(E25:E34,">=1")=0,COUNTA(E25:E34),COUNTIF(D25:D34,">=1")) -> 0 | F35: =SUMIF(F25:F34,">=1")/IF(COUNTIF(F25:F34,">=1")=0,COUNTA(F25:F34),COUNTIF(D25:D34,">=1")) -> 0 | G35: =SUMIF(G25:G34,">=1")/IF(COUNTIF(G25:G34,">=1")=0,COUNTA(G25:G34),COUNTIF(D25:D34,">=1")) -> 0
B37: Module Name | C37: Iterations | D37: Total Test Cases Executed | E37: Pass | F37: Fail | G37: Not Tested
B38: =TC_Progress!C$7 -> TC_Progress | C38: Iteration - 1 | D38: =SUM(COUNTIF(TC_Progress!L$10:L$2523,"Pass")+COUNTIF(TC_Progress!L$10:L$2523,"Fail")+COUNTIF(TC_Progress!L$10:L$2523,"Not Tested")) -> 0 | E38: =COUNTIF(TC_Progress!L$10:L$2524, "Pass") -> 0 | F38: =COUNTIF(TC_Progress!L$10:L$2524, "Fail") -> 0 | G38: =COUNTIF(TC_Progress!L$10:L$2524, "Not Tested") -> 0
C39: Iteration - 2 | D39: =SUM(COUNTIF(TC_Progress!R$10:R$2523,"Pass")+COUNTIF(TC_Progress!R$10:R$2523,"Fail")+COUNTIF(TC_Progress!R$10:R$2523,"Not Tested")) -> 0 | E39: =COUNTIF(TC_Progress!R$10:R$2524, "Pass") -> 0 | F39: =COUNTIF(TC_Progress!R$10:R$2524, "Fail") -> 0 | G39: =COUNTIF(TC_Progress!R$10:R$2524, "Not Tested") -> 0
C40: Iteration - 3 | D40: =SUM(COUNTIF(TC_Progress!X$10:X$2523,"Pass")+COUNTIF(TC_Progress!X$10:X$2523,"Fail")+COUNTIF(TC_Progress!X$10:X$2523,"Not Tested")) -> 0 | E40: =COUNTIF(TC_Progress!X$10:X$2524, "Pass") -> 0 | F40: =COUNTIF(TC_Progress!X$10:X$2524, "Fail") -> 0 | G40: =COUNTIF(TC_Progress!X$10:X$2524, "Not Tested") -> 0
C41: Iteration - 4 | D41: =SUM(COUNTIF(TC_Progress!AD$10:AD$2523,"Pass")+COUNTIF(TC_Progress!AD$10:AD$2523,"Fail")+COUNTIF(TC_Progress!AD$10:AD$2523,"Not Tested")) -> 0 | E41: =COUNTIF(TC_Progress!AD$10:AD$2524, "Pass") -> 0 | F41: =COUNTIF(TC_Progress!AD$10:AD$2524, "Fail") -> 0 | G41: =COUNTIF(TC_Progress!AD$10:AD$2524, "Not Tested") -> 0
C42: Iteration - 5 | D42: =SUM(COUNTIF(TC_Progress!AJ$10:AJ$2523,"Pass")+COUNTIF(TC_Progress!AJ$10:AJ$2523,"Fail")+COUNTIF(TC_Progress!AJ$10:AJ$2523,"Not Tested")) -> 0 | E42: =COUNTIF(TC_Progress!AJ$10:AJ$2524, "Pass") -> 0 | F42: =COUNTIF(TC_Progress!AJ$10:AJ$2524, "Fail") -> 0 | G42: =COUNTIF(TC_Progress!AJ$10:AJ$2524, "Not Tested") -> 0
C43: Iteration - 6 | D43: =SUM(COUNTIF(TC_Progress!AP$10:AP$2523,"Pass")+COUNTIF(TC_Progress!AP$10:AP$2523,"Fail")+COUNTIF(TC_Progress!AP$10:AP$2523,"Not Tested")) -> 0 | E43: =COUNTIF(TC_Progress!AP$10:AP$2524, "Pass") -> 0 | F43: =COUNTIF(TC_Progress!AP$10:AP$2524, "Fail") -> 0 | G43: =COUNTIF(TC_Progress!AP$10:AP$2524, "Not Tested") -> 0
C44: Iteration - 7 | D44: =SUM(COUNTIF(TC_Progress!AV$10:AV$2523,"Pass")+COUNTIF(TC_Progress!AV$10:AV$2523,"Fail")+COUNTIF(TC_Progress!AV$10:AV$2523,"Not Tested")) -> 0 | E44: =COUNTIF(TC_Progress!AV$10:AV$2524, "Pass") -> 0 | F44: =COUNTIF(TC_Progress!AV$10:AV$2524, "Fail") -> 0 | G44: =COUNTIF(TC_Progress!AV$10:AV$2524, "Not Tested") -> 0
C45: Iteration - 8 | D45: =SUM(COUNTIF(TC_Progress!BB$10:BB$2523,"Pass")+COUNTIF(TC_Progress!BB$10:BB$2523,"Fail")+COUNTIF(TC_Progress!BB$10:BB$2523,"Not Tested")) -> 0 | E45: =COUNTIF(TC_Progress!BB$10:BB$2524, "Pass") -> 0 | F45: =COUNTIF(TC_Progress!BB$10:BB$2524, "Fail") -> 0 | G45: =COUNTIF(TC_Progress!BB$10:BB$2524, "Not Tested") -> 0
...

Sheet TC_Common
F2: Diaspark Inc. | H2: DP-TFACMM-TCD-V1.1
B3: Test Cases
B4: Document Reference | C4: RequirementsDetailedUseCases | F4: Environment | G4: FF,IE8,9,Google Chrome's
B5: Test Type | C5: Functional | F5: Brief Description | G5: System testing including functional,compatablity ,UI Testing of MTLD-CM
B6: Project Name | C6: MTLD-CM Matching Tool | F6: Reviewed By | G6: Alok Tapdiya,Arun Rathore
B7: Module Name | C7: TC_Common | F7: Approved By | G7: Alok Tapdiya
B9: Created By | C9: Created on | D9: Requirement/Task ID | E9: Test case ID | F9: Test Case Objective | G9: Test Steps /Procedure | H9: Test Data (Optional) | I9: Importance /Priority | J9: Expected Result | K9: Actual Result (Iteration 1) | L9: Status (Iteration 1) | M9: Bug ID (Iteration 1) | N9: Execution Date (Iteration 1) | O9: Executed By (Iteration 1) | P9: Comments (Iteration 1) | Q9: Actual Result (Iteration 2) | R9: Status (Iteration 2) | S9: Bug ID (Iteration 2) | T9: Execution Date (Iteration 2) | U9: Executed By (Iteration 2) | V9: Comments (Iteration 2) | W9: Actual Result (Iteration 3) | X9: Status (Iteration 3) | Y9: Bug ID (Iteration 3) | Z9: Execution Date (Iteration 3) | AA9: Executed By (Iteration 3) | AB9: Comments (Iteration 3) | AC9: Actual Result (Iteration 4) | AD9: Status (Iteration 4) | AE9: Bug ID (Iteration 4) | AF9: Execution Date (Iteration 4) | AG9: Executed By (Iteration 4) | AH9: Comments (Iteration 4) | AI9: Actual Result (Iteration 5) | AJ9: Status (Iteration 5) | AK9: Bug ID (Iteration 5) | AL9: Execution Date (Iteration 5) | AM9: Executed By (Iteration 5) | AN9: Comments (Iteration 5) | AO9: Actual Result (Iteration 6) | AP9: Status (Iteration 6) | AQ9: Bug ID (Iteration 6) | AR9: Execution Date (Iteration 6) | AS9: Executed By (Iteration 6) | AT9: Comments (Iteration 6) | AU9: Actual Result (Iteration 7) | AV9: Status (Iteration 7) | AW9: Bug ID (Iteration 7) | AX9: Execution Date (Iteration 7) | AY9: Executed By (Iteration 7) | AZ9: Comments (Iteration 7) | BA9: Actual Result (Iteration 8) | BB9: Status (Iteration 8) | BC9: Bug ID (Iteration 8) | BD9: Execution Date (Iteration 8) | BE9: Executed By (Iteration 8) | BF9: Comments (Iteration 8) | BG9: Actual Result (Iteration 9) | BH9: Status (Iteration 9) | BI9: Bug ID (Iteration 9) | BJ9: Execution Date (Iteration 9) | BK9: Executed By (Iteration 9) | BL9: Comments (Iteration 9) | BM9: Actual Result (Iteration 10) | BN9: Status (Iteration 10) | BO9: Bug ID (Iteration 10) | BP9: Execution Date (Iteration 10) | BQ9: Executed By (Iteration 10) | BR9: Comments (Iteration 10)
B10: Rakesh Kumar Singh | C10: 41703 | D10: URL Accessibility | E10: TC-TFACMM-1.0.1 | F10: To Check the URL is accessible | G10: Access the given URL. | I10: Low | J10: Application should be accessible and Home page should be displayed. | K10: As Expected working | L10: <Select> | R10: <Select> | X10: <Select> | AD10: <Select> | AJ10: <Select> | AP10: <Select> | AV10: <Select> | BB10: <Select> | BH10: <Select> | BN10: <Select>
B11: Rakesh Kumar Singh | C11: 41703 | D11: check GUI behavior of login window | E11: TC-TFACMM-1.0.2 | F11: To check the GUI behavior of login window. | G11: Access the application. | I11: Low | J11: Application should be displayed a login window with following content. 1. Window title " TEACHFORAMERICA logo's-MTLD Matching Application 2. Text box for "TeachForAmerica ID" 3. Text box for Password 4. Login button 5. Remember password with check box Mark 9. Option for close window Note: 1. All content should be matched with Prototype. 2. All font face and font style, alignment, background should be based on prototype. 3. Cursor should be focused on Email textbox | L11: <Select> | R11: <Select> | X11: <Select> | AD11: <Select> | AJ11: <Select> | AP11: <Select> | AV11: <Select> | BB11: <Select> | BH11: <Select> | BN11: <Select>
B12: Rakesh Kumar Singh | C12: 41703 | D12: Login | E12: TC-TFACMM-1.0.3 | F12: Test the application response when User clicks on "Login" button after entering valid data | G12: 1.) Enter a valid "TeachForAmerica ID" in the field 2.) Enter a valid password in the field 3.) Click on "Login" button | I12: Low | J12: Application should allow user to logged in on the system and displayed specific Region | L12: <Select> | R12: <Select> | X12: <Select> | AD12: <Select> | AJ12: <Select> | AP12: <Select> | AV12: <Select> | BB12: <Select> | BH12: <Select> | BN12: <Select>
B13: Rakesh Kumar Singh | C13: 41703 | D13: Login | E13: TC-TFACMM-1.0.4 | F13: Verify that User is not able to login with invalid login and invalid password. | G13: 1. Access the Application. 2. Logged in with invalid Email/Username and valid password. | I13: Low | J13: System should display a validation message saying "Invalid e-mail address or password. Please try again" | L13: <Select> | R13: <Select> | X13: <Select> | AD13: <Select> | AJ13: <Select> | AP13: <Select> | AV13: <Select> | BB13: <Select> | BH13: <Select> | BN13: <Select>
B14: Rakesh Kumar Singh | C14: 41703 | D14: Login | E14: TC-TFACMM-1.0.5 | F14: Verify that valid TFA ID and Invalided Password . | G14: 1. Access the Application. 2. Logged in with Valid TFA ID and Invalided password. 3. click on Login button | I14: Low | J14: A Message "invalid Password" should be displayed and the cursor should wait in the password field | L14: <Select> | R14: <Select> | X14: <Select> | AD14: <Select> | AJ14: <Select> | AP14: <Select> | AV14: <Select> | BB14: <Select> | BH14: <Select> | BN14: <Select>
B15: Rakesh Kumar Singh | C15: 41703 | D15: Login | E15: TC-TFACMM-1.0.6 | F15: Verify that invalid TFA ID and valid Password . | G15: 1. Access the Application. 2. Logged in with Invalided TFA ID and valid password. 3. click on Login button | I15: Low | J15: A Message "invalid TFA ID " should be displayed and the cursor should wait in the password field | L15: <Select> | R15: <Select> | X15: <Select> | AD15: <Select> | AJ15: <Select> | AP15: <Select> | AV15: <Select> | BB15: <Select> | BH15: <Select> | BN15: <Select>
B16: Rakesh Kumar Singh | C16: 41703 | D16: Login | E16: TC-TFACMM-1.0.7 | F16: To check the functionality of logout link | G16: 1. Access the application 2. Login with valid Email and Valid password 3. Click on logout link | I16: Low | J16: application should redirect the user to application home page. | L16: <Select> | R16: <Select> | X16: <Select> | AD16: <Select> | AJ16: <Select> | AP16: <Select> | AV16: <Select> | BB16: <Select> | BH16: <Select> | BN16: <Select>
B17: Rakesh Kumar Singh | C17: 41703 | D17: Login | E17: TC-TFACMM-1.0.8 | F17: After logging out click on back button in the browser | G17: 1. Access the application 2. Login with valid Email and Valid password 3. Click on logout link 4. click on back button in the browser. | I17: Low | J17: should not go to the Previous page expected. | L17: <Select> | R17: <Select> | X17: <Select> | AD17: <Select> | AJ17: <Select> | AP17: <Select> | AV17: <Select> | BB17: <Select> | BH17: <Select> | BN17: <Select>
B18: Rakesh Kumar Singh | C18: 41704 | D18: Dashboard | E18: TC-TFACMM-1.0.9 | F18: To Check the GUI behavior of "criteria page" | G18: Access the given URL. 1.) Enter a valid email id in the field 2.) Enter a valid password in the field 3.) Click on "Login" button 4.) Criteria page should be displayed. | I18: Low | J18: 1. Application "Criteria Page" should be displayed and content should be matched with Prototype. 2. All font face and font style, alignment, background should be based on prototype. 3. Screen should have Three Sections as (a) Criteria Select (b) CM Cohorts (c) MTLD Info 4. Select Your Criteria(s) (a) Basics (b) Content (c) Geographic (d) Relationships 5. Region name should be displayed right corner (a) Region Name Set Priority displayed under the Right corner 6. Two check box should be displayed 1) Include MTLD info for CM-MTLD pairing? 2) Include unhired CMs in matches? 7. Banner section should be displayed banner for Teach For America with LOGO. 8.Right Conner my account and logout link should be displayed 9. Content area section should have subsections as. 10.To check the user able to access the help text Note : (1) On click, all links should navigate to their respective pages. (2) Tab control should be from left to right and top to bottom. (3) On hovering mouse over Tab navigations , a dropdown should appear with submenu items if any. | L18: <Select> | R18: <Select>
B19: Rakesh Kumar Singh | C19: 41704 | D19: Dashboard | E19: TC-TFACMM-1.0.10 | F19: To Check the GUI behavior of "CM Cohorts'' | G19: Access the given URL. 1.) Enter a valid email id in the field 2.) Enter a valid password in the field 3.) Click on "Login" button | I19: Low | J19: 1. Application "CM Cohorts" should be displayed and content should be matched with Prototype. 2. All font face and font style, alignment, background should be based on prototype. 3. Screen should have Three Sections as (a) Criteria Select (b) CM Cohorts (c) MTLD Info 4. Criteria Match Progress should be displayed right corner 5. Region name should be displayed right corner (a) Region Name Google map should be displayed under the CM Cohorts 6. corps Member should be displayed under the Left cohorts droop down we have 1) CMs Number 2) CM-MTLD 3) UNHIRED CMs also we have search by drop down 1) by name 2) by Region under the Cohorts we have MTLD and Corps Member 7. Banner section should be displayed banner for Teach For America with LOGO. 8.Right Conner my account and logout link should be displayed 9. Content area section should have subsections as. 10. also we have export and rematch button in under the cohorts. 11. To check the user able to access the help text Note : (1) On click, all links should navigate to their respective pages. (2) Tab control should be from left to right and top to bottom. (3) On hovering mouse over Tab navigations , a dropdown should appear with submenu items if any. | L19: <Select> | R19: <Select>
B20: Rakesh Kumar Singh | C20: 41716 | D20: Cross-Browser | E20: TC-TFACMM-1.0.11 | F20: To Check that Test Cases From TC-1 To TC-19 should be Pass | G20: 1. Execute Test Case from TC-1 to TC-19 on different browser | H20: 1.FF 2.IE 3.Google Chrome 4.Safari | I20: Low | J20: All Test Case from TC-1 to TC-19 should be pass. | L20: <Select> | R20: <Select>
L21: <Select> | R21: <Select>
L22: <Select> | R22: <Select>
L23: <Select> | R23: <Select>
L24: <Select> | R24: <Select>
L25: <Select> | R25: <Select>
L26: <Select> | R26: <Select>
L27: <Select> | R27: <Select>
L28: <Select> | R28: <Select>
L29: <Select> | R29: <Select>
L30: <Select> | R30: <Select>
L31: <Select> | R31: <Select>
L32: <Select> | R32: <Select>
... L36: <Select> | R36: <Select>

Sheet TC_Progress
F2: Diaspark Inc. | H2: DP-TFACMM-TCD-V1.1
B3: Test Cases
B4: Document Reference | C4: RequirementsDetailedUseCases | F4: Environment | G4: FF,IE8,9,Google Chrome
B5: Test Type | C5: Functional | F5: Brief Description | G5: System testing including functional,compatablity ,UI Testing of MTLD-CM
B6: Project Name | C6: MTLD-CM Matching Tool | F6: Reviewed By | G6: Alok Tapdiya,Arun Rathore
B7: Module Name | C7: TC_Progress | F7: Approved By | G7: Alok Tapdiya
B9: Created By | C9: Created on | D9: Requirement/Task ID | E9: Test case ID | F9: Test Case Objective | G9: Test Steps /Procedure | H9: Test Data (Optional) | I9: Importance /Priority | J9: Expected Result | K9: Actual Result (Iteration 1) | L9: Status (Iteration 1) | M9: Bug ID (Iteration 1) | N9: Execution Date (Iteration 1) | O9: Executed By (Iteration 1) | P9: Comments (Iteration 1) | Q9: Actual Result (Iteration 2) | R9: Status (Iteration 2) | S9: Bug ID (Iteration 2) | T9: Execution Date (Iteration 2) | U9: Executed By (Iteration 2) | V9: Comments (Iteration 2) | W9: Actual Result (Iteration 3) | X9: Status (Iteration 3) | Y9: Bug ID (Iteration 3) | Z9: Execution Date (Iteration 3) | AA9: Executed By (Iteration 3) | AB9: Comments (Iteration 3) | AC9: Actual Result (Iteration 4) | AD9: Status (Iteration 4) | AE9: Bug ID (Iteration 4) | AF9: Execution Date (Iteration 4) | AG9: Executed By (Iteration 4) | AH9: Comments (Iteration 4) | AI9: Actual Result (Iteration 5) | AJ9: Status (Iteration 5) | AK9: Bug ID (Iteration 5) | AL9: Execution Date (Iteration 5) | AM9: Executed By (Iteration 5) | AN9: Comments (Iteration 5) | AO9: Actual Result (Iteration 6) | AP9: Status (Iteration 6) | AQ9: Bug ID (Iteration 6) | AR9: Execution Date (Iteration 6) | AS9: Executed By (Iteration 6) | AT9: Comments (Iteration 6) | AU9: Actual Result (Iteration 7) | AV9: Status (Iteration 7) | AW9: Bug ID (Iteration 7) | AX9: Execution Date (Iteration 7) | AY9: Executed By (Iteration 7) | AZ9: Comments (Iteration 7) | BA9: Actual Result (Iteration 8) | BB9: Status (Iteration 8) | BC9: Bug ID (Iteration 8) | BD9: Execution Date (Iteration 8) | BE9: Executed By (Iteration 8) | BF9: Comments (Iteration 8) | BG9: Actual Result (Iteration 9) | BH9: Status (Iteration 9) | BI9: Bug ID (Iteration 9) | BJ9: Execution Date (Iteration 9) | BK9: Executed By (Iteration 9) | BL9: Comments (Iteration 9) | BM9: Actual Result (Iteration 10) | BN9: Status (Iteration 10) | BO9: Bug ID (Iteration 10) | BP9: Execution Date (Iteration 10) | BQ9: Executed By (Iteration 10) | BR9: Comments (Iteration 10)
B10: Rakesh Kumar Singh | C10: 41704 | D10: Criteria Match Progress | E10: TC-TFACMM-1.0.12 | F10: To check the functionality of "Make my Match "Button when user not selected any criteria. | G10: 1.Access the Application. 2.Logged in with Valid TFA ID and valid password. 3.click on Login button. 4. Don’t select any criteria and click on MAKE MY MATCHES | I10: High | J10: Application should not display progress bar. Note: Progress bar should be displayed only for priority 3 & 4. | L10: <Select> | R10: <Select> | X10: <Select> | AD10: <Select> | AJ10: <Select> | AP10: <Select> | AV10: <Select> | BB10: <Select> | BH10: <Select> | BN10: <Select>
B11: Rakesh Kumar Singh | C11: 41704 | D11: Criteria Match Progress | E11: TC-TFACMM-1.0.13 | F11: To verify the matched percentage displayed on progress bar | G11: 1.Access the Application. 2.Logged in with Valid TFA ID and valid password. 3.click on Login button. 4.select priority 3 Or 4. 5.click on Make my matches button. | I11: High | J11: As per Criteria Match Progress should be displayed in %. Formula used to calculate the % is :( #of CM match with the criteria/Total # of CMs in the region)*100 | L11: <Select> | R11: <Select> | X11: <Select> | AD11: <Select> | AJ11: <Select> | AP11: <Select> | AV11: <Select> | BB11: <Select> | BH11: <Select> | BN11: <Select>
B12: Rakesh Kumar Singh | C12: 41704 | D12: Criteria Match Progress | E12: TC-TFACMM-1.0.14 | F12: Verify Overall Progress percentage | G12: 1.Access the Application. 2.Logged in with Valid TFA ID and valid password. 3.click on Login button. 4.select priority 3 Or 4. 5.click on Make my matches button. | I12: High | J12: Overall progress percentage should be the mean of all selected criteria whose priority is 3 or 4. | L12: <Select> | R12: <Select> | X12: <Select> | AD12: <Select> | AJ12: <Select> | AP12: <Select> | AV12: <Select> | BB12: <Select> | BH12: <Select> | BN12: <Select>
B13: Rakesh Kumar Singh | C13: 41704 | D13: Criteria Match Progress | E13: TC-TFACMM-1.0.15 | F13: Verify the Progress bar Color combinations Should be according to our Requirement | G13: 1.Access the Application. 2.Logged in with Valid TFA ID and valid password. 3.click on Login button. 4.select some Criteria and prioritize. 5.click on Make my matches button. | I13: High | J13: color combination should be displayed as per the Requirement | L13: <Select> | R13: <Select> | X13: <Select> | AD13: <Select> | AJ13: <Select> | AP13: <Select> | AV13: <Select> | BB13: <Select> | BH13: <Select> | BN13: <Select>
B14: Rakesh Kumar Singh | C14: 41704 | D14: Criteria Match Progress | E14: TC-TFACMM-1.0.16 | F14: Scroll-bar need to be available to see the entire Progress graph | G14: 1.Access the Application. 2.Logged in with Valid TFA ID and valid password. 3.click on Login button. 4.select some Criteria and prioritize. 5.click on Make my matches button. | I14: High | J14: Scroll bar working as expected | L14: <Select> | R14: <Select> | X14: <Select> | AD14: <Select> | AJ14: <Select> | AP14: <Select> | AV14: <Select> | BB14: <Select> | BH14: <Select> | BN14: <Select>
L15: <Select> | R15: <Select> | X15: <Select> | AD15: <Select> | AJ15: <Select> | AP15: <Select> | AV15: <Select> | BB15: <Select> | BH15: <Select> | BN15: <Select>
L16: <Select>
L17: <Select>
L18: <Select>
L19: <Select>
L20: <Select>
L21: <Select>
L22: <Select>
L23: <Select>
L24: <Select>
L25: <Select>
L26: <Select>
L27: <Select>
... L29: <Select>
L30: <Select> | R30: <Select> | X30: <Select> | AD30: <Select> | AJ30: <Select> | AP30: <Select> | AV30: <Select> | BB30: <Select> | BH30: <Select> | BN30: <Select>
L31: <Select> | R31: <Select> | X31: <Select> | AD31: <Select> | AJ31: <Select> | AP31: <Select> | AV31: <Select> | BB31: <Select> | BH31: <Select> | BN31: <Select>

Sheet TC_Cohort
F2: Dias park Inc. | H2: =TC_Common!H2 -> DP-TFACMM-TCD-V1.1
B3: Test Cases
B4: Document Reference | C4: RequirementsDetailedUseCases | F4: Environment | G4: FF,IE8,9,Google Chrome
B5: Test Type | C5: Functional | F5: Brief Description | G5: System testing including functional,compatablity ,UI Testing of MTLD-CM
B6: Project Name | C6: MTLD-CM Matching Tool | F6: Reviewed By | G6: Alok Tapdiya,Arun Rathore
B7: Module Name | C7: TC_Cohort | F7: Approved By | G7: Alok Tapdiya
B9: Created By | C9: Created on | D9: Requirement/Task ID | E9: Test case ID | F9: Test Case Objective | G9: Test Steps /Procedure | H9: Test Data (Optional) | I9: Importance /Priority | J9: Expected Result | K9: Actual Result (Iteration 1) | L9: Status (Iteration 1) | M9: Bug ID (Iteration 1) | N9: Execution Date (Iteration 1) | O9: Executed By (Iteration 1) | P9: Comments (Iteration 1) | Q9: Actual Result (Iteration 2) | R9: Status (Iteration 2) | S9: Bug ID (Iteration 2) | T9: Execution Date (Iteration 2) | U9: Executed By (Iteration 2) | V9: Comments (Iteration 2) | W9: Actual Result (Iteration 3) | X9: Status (Iteration 3) | Y9: Bug ID (Iteration 3) | Z9: Execution Date (Iteration 3) | AA9: Executed By (Iteration 3) | AB9: Comments (Iteration 3) | AC9: Actual Result (Iteration 4) | AD9: Status (Iteration 4) | AE9: Bug ID (Iteration 4) | AF9: Execution Date (Iteration 4) | AG9: Executed By (Iteration 4) | AH9: Comments (Iteration 4) | AI9: Actual Result (Iteration 5) | AJ9: Status (Iteration 5) | AK9: Bug ID (Iteration 5) | AL9: Execution Date (Iteration 5) | AM9: Executed By (Iteration 5) | AN9: Comments (Iteration 5) | AO9: Actual Result (Iteration 6) | AP9: Status (Iteration 6) | AQ9: Bug ID (Iteration 6) | AR9: Execution Date (Iteration 6) | AS9: Executed By (Iteration 6) | AT9: Comments (Iteration 6) | AU9: Actual Result (Iteration 7) | AV9: Status (Iteration 7) | AW9: Bug ID (Iteration 7) | AX9: Execution Date (Iteration 7) | AY9: Executed By (Iteration 7) | AZ9: Comments (Iteration 7) | BA9: Actual Result (Iteration 8) | BB9: Status (Iteration 8) | BC9: Bug ID (Iteration 8) | BD9: Execution Date (Iteration 8) | BE9: Executed By (Iteration 8) | BF9: Comments (Iteration 8) | BG9: Actual Result (Iteration 9) | BH9: Status (Iteration 9) | BI9: Bug ID (Iteration 9) | BJ9: Execution Date (Iteration 9) | BK9: Executed By (Iteration 9) | BL9: Comments (Iteration 9) | BM9: Actual Result (Iteration 10) | BN9: Status (Iteration 10) | BO9: Bug ID (Iteration 10) | BP9: Execution Date (Iteration 10) | BQ9: Executed By (Iteration 10) | BR9: Comments (Iteration 10)
B10: Rakesh Kumar Singh | C10: 41703 | D10: Cohort | E10: TC-TFACMM-1.0.17 | F10: Verify the Cohort name | G10: 1.) Enter a valid "TeachForAmerica ID" in the field 2.) Enter a valid password in the field 3.) Click on "Login" button 4.) select criteria and click on "Make My Match" 5.) Cohort page should be displayed. | I10: High | J10: Default should set to the Cohort 1, 2, under the cohort OR Name as per user input | L10: <Select> | R10: <Select> | X10: <Select> | AD10: <Select> | AJ10: <Select> | AP10: <Select> | AV10: <Select> | BB10: <Select> | BH10: <Select> | BN10: <Select>
B11: Rakesh Kumar Singh | C11: 41724 | D11: Cohort | E11: TC-TFACMM-1.0.18 | F11: Verify On the content on cohort detail page. | G11: 1. Enter a valid "TeachForAmerica ID" in the field 2. Enter a valid password in the field 3. Click on "Login" button 4. Criteria Select Page should be displayed. 5.selects value for each criterion and enters in any additionally required values (e.g.#schools/MTLD) and clicks 6.Click the check box(unhired CMs and CM-MTLD pairing? ) and press the Make my matches button 7. CM Cohorts page should be displayed. | J11: Top-line: ● # CMs in group ● # schools represented ● diameter (in mi) between two furthest schools (Miles apart (max) ) ● a ‘warning light’ or other visual indicator if CMs are outside the constrained travel distance ●“%criteria matched” to 4 different numbers: • Basics Score • Content Score • Geography Score • Relationships Score Note: 1)Need to verify for all the cohort 2) Count of cohort should be as defined on database as per the region | L11: <Select> | R11: <Select> | X11: <Select> | AD11: <Select> | AJ11: <Select> | AP11: <Select> | AV11: <Select> | BB11: <Select> | BH11: <Select> | BN11: <Select>
B12: Rakesh Kumar Singh | C12: 41703 | D12: Cohort | E12: TC-TFACMM-1.0.19 | F12: Verify the #CMs in cohort | G12: 1.) Enter a valid "TeachForAmerica ID" in the field 2.) Enter a valid password in the field 3.) Click on "Login" button 4.)select criteria and click on "Make My Match" 5.) Cohort page should be displayed. 6) Verify the # CMs cohort | I12: High | J12: 1) IF criteria for MLTD and CMs is selected than each cohort should not have cms more than the defined number. 2) If no criteria is selected for ration than each cohort should have each CMs in cohort. Formula used for it = # of cms in the region/ total number of groups in the region. Note: Each group can have maximum 30 CMs only. | L12: <Select> | R12: <Select> | X12: <Select> | AD12: <Select> | AJ12: <Select> | AP12: <Select> | AV12: <Select> | BB12: <Select> | BH12: <Select> | BN12: <Select>
B13: Rakesh Kumar Singh | C13: 41703 | D13: Cohort | E13: TC-TFACMM-1.0.20 | F13: Verify # schools represented in school | G13: 1.) Enter a valid "TeachForAmerica ID" in the field 2.) Enter a valid password in the field 3.) Click on "Login" button 4.)select criteria and click on "Make My Match" 5.) Cohort page should be displayed. 6) Verify # schools represented in school | I13: High | J13: Count of unique schools per cohort should be displayed | L13: <Select> | R13: <Select> | X13: <Select> | AD13: <Select> | AJ13: <Select> | AP13: <Select> | AV13: <Select> | BB13: <Select> | BH13: <Select> | BN13: <Select>
B14: Rakesh Kumar Singh | C14: 41703 | D14: Cohort | E14: TC-TFACMM-1.0.21 | F14: Verify Distance between schools | G14: 1.) Enter a valid "TeachForAmerica ID" in the field 2.) Enter a valid password in the field 3.) Click on "Login" button 4.)select criteria and click on "Make My Match" 5.) Cohort page should be displayed. 6) Verify Distance between schools | I14: High | J14: Value entered by the user on criteria selection page should be displayed in cohort. If Cohort is locked than it should displayed previous entered value else new entered value. | L14: <Select> | R14: <Select> | X14: <Select> | AD14: <Select> | AJ14: <Select> | AP14: <Select> | AV14: <Select> | BB14: <Select> | BH14: <Select> | BN14: <Select>
B15: Rakesh Kumar Singh | C15: 41724 | D15: Cohort | E15: TC-TFACMM-1.0.22 | F15: Verify Over distance indicator light functionality. | G15: 1. Enter a valid "TeachForAmerica ID" in the field 2. Enter a valid password in the field 3. Click on "Login" button 4. Criteria Select Page should be displayed. 5.selects value for each criterion and enters in any additionally required values (e.g.#schools/MTLD) and clicks 6.Click the check box(unhired CMs and CM-MTLD pairing? ) and press the Make my matches button 7. CM Cohorts page should be displayed. | J15: TO BE discussed. Note :‘mouse over’ should be displays text “over distance limit” | L15: <Select> | R15: <Select> | X15: <Select> | AD15: <Select> | AJ15: <Select> | AP15: <Select> | AV15: <Select> | BB15: <Select> | BH15: <Select> | BN15: <Select>
B16: Rakesh Kumar Singh | C16: 41703 | D16: Cohort | E16: TC-TFACMM-1.0.23 | F16: verify the “%criteria matched” for Basics Score under the cohorts | G16: 1.) Enter a valid "TeachForAmerica ID" in the field 2.) Enter a valid password in the field 3.) Click on "Login" button 4.)select criteria and click on "Make My Match" 5.) Cohort page should be displayed. | I16: High | J16: percent of corps members should be displayed for basics formula:- Basics Score: cumulative score for= (C1+C2+ C3)/3 | L16: <Select> | R16: <Select> | X16: <Select> | AD16: <Select> | AJ16: <Select> | AP16: <Select> | AV16: <Select> | BB16: <Select> | BH16: <Select> | BN16: <Select>
B17: Rakesh Kumar Singh | C17: 41703 | D17: Cohort | E17: TC-TFACMM-1.0.24 | F17: verify the “%criteria matched” for Content Score under the cohorts | G17: 1.) Enter a valid "TeachForAmerica ID" in the field 2.) Enter a valid password in the field 3.) Click on "Login" button 4.)select criteria and click on "Make My Match" 5.) Cohort page should be displayed. | I17: High | J17: percent of corps members should be displayed for Content Score formula:- Ex: Content Score: cumulative score for (C4+C5+C6)/3
B18: Rakesh Kumar Singh | C18: 41703 | D18: Cohort | E18: TC-TFACMM-1.0.25 | F18: verify the “%criteria matched” for Geography Score under the cohorts | G18: 1.) Enter a valid "TeachForAmerica ID" in the field 2.) Enter a valid password in the field 3.) Click on "Login" button 4.)select criteria and click on "Make My Match" 5.) Cohort page should be displayed. | I18: High | J18: percent of corps members should be displayed for Content Score formula:- • Ex: Geography: cumulative score for C7+C8+C9+C10+ C11/5
B19: Rakesh Kumar Singh | C19: 41703 | D19: Cohort | E19: TC-TFACMM-1.0.26 | F19: verify the “%criteria matched” for Relationships Score under the cohorts | G19: 1.) Enter a valid "TeachForAmerica ID" in the field 2.) Enter a valid password in the field 3.) Click on "Login" button 4.)select criteria and click on "Make My Match" 5.) Cohort page should be displayed. | I19: High | J19: percent of corps members should be displayed for Content Score formula:- Ex: • Relationships Score: cumulative score for (C12+C13+C14+C15+C16)/5
B20: Rakesh Kumar Singh | C20: 41710 | D20: Cohort | E20: TC-TFACMM-1.0.27 | F20: To Verify the save button functionality present on each cohort. | G20: 1. Enter a valid "TeachForAmerica ID" in the field 2. Enter a valid password in the field 3. Click on "Login" button 4. Criteria Select Page should be displayed. 5.selects value for each criterion and enters in any additionally required values (e.g.#schools/MTLD) and clicks 6.Click the check box(unhired CMs and CM-MTLD pairing? ) and press the Make my matches button 7. CM Cohorts page should be displayed. 8.click on Save button under the cluster. | I20: High | J20: Application should lock the cohort and Unlock button should be appear. Note: Locked group should not be editable untill and unless user unlocked the group.
B21: Rakesh Kumar Singh | C21: 41724 | D21: Cohort | E21: TC-TFACMM-1.0.28 | F21: Verify group detail pop-up when click on the cohort. | G21: 1. Enter a valid "TeachForAmerica ID" in the field 2. Enter a valid password in the field 3. Click on "Login" button 4. Criteria Select Page should be displayed. 5.selects value for each criterion and enters in any additionally required values (e.g.#schools/MTLD) and clicks 6.Click the check box(unhired CMs and CM-MTLD pairing? ) and press the Make my matches button 7. CM Cohorts page should be displayed. | J21: Group pop up should be displayed with following - detail (when clicked to expand) Detail: ● # of school districts represented ● # of region-defined sub-geography in cluster ● % of cohort teaching SPED ● % ECE CMs ● % first year CMs ● % second year CMs ● % of cohort teaching in charter schools ● % of cohort teaching in public district schools ● % ELEM ● % MS ● % HS ● % POC ● % coming from low income background ● Feeder pattern HS
B22: Rakesh Kumar Singh | C22: 41703 | D22: Cohort | E22: TC-TFACMM-1.0.29 | F22: Verify # school districts represented on group popup window | G22: Open the group popup window. 2) Verify the count of school. | I22: High | J22: Count of unique school districts should be displayed per cohort
B23: Rakesh Kumar Singh | C23: 41703 | D23: Cohort | E23: TC-TFACMM-1.0.30 | F23: Verify # sub-geography represented on group popup window | G23: Open the group popup window. 2) Verify the count. | I23: High | J23: count of sub-geography represented should be displayed under the cohorts
B24: Rakesh Kumar Singh | C24: 41703 | D24: Cohort | E24: TC-TFACMM-1.0.31 | F24: Verify % with SPED modifier present on group popup window | G24: Open the group popup window. 2) Verify % with SPED modifier present on group popup window | I24: High | J24: percent of cohort should be displayed with "subject modifier" containing "SPED"
B25: Rakesh Kumar Singh | C25: 41703 | D25: Cohort | E25: TC-TFACMM-1.0.32 | F25: Verify % ECE present on group popup window | G25: Open the group popup window. 2) Verify % ECE present on group popup window | I25: High | J25: percent of cohort should be displayed with "subject modifier" containing "ECE"
B26: Rakesh Kumar Singh | C26: 41703 | D26: Cohort | E26: TC-TFACMM-1.0.33 | F26: verify % 1CM and % 2CM on group popup window | G26: Open the group popup window. 2) Verify% 1CM and % 2CM present on group popup window | I26: High | J26: percent of cohort who are first year CM (corps year = 2014) percent of cohort who are second year CM (corps year = 2013 or lower) should be displayed
B27: Rakesh Kumar Singh | C27: 41703 | D27: Cohort | E27: TC-TFACMM-1.0.34 | F27: verify % charter and % public district on group popup window | G27: Open the group popup window. 2) Verify% charter and % public district present on group popup window | I27: High | J27: charter and public district % should be displayed under the cohort | L27: <Select> | R27: <Select> | X27: <Select> | AD27: <Select> | AJ27: <Select> | AP27: <Select> | AV27: <Select> | BB27: <Select> | BH27: <Select> | BN27: <Select>
B28: Rakesh Kumar Singh | C28: 41703 | D28: Cohort | E28: TC-TFACMM-1.0.35 | F28: verify % Elem on group popup window | G28: Open the group popup window. 2) Verify% Elem on group popup window | I28: High | J28: percent of cohort should be displayed Grade Level contain "Elem" under the Cohort pop up .
B29: Rakesh Kumar Singh | C29: 41703 | D29: Cohort | E29: TC-TFACMM-1.0.36 | F29: verify % MS and % HS on group popup window | G29: Open the group popup window. 2) Verify % MS and % HS on group popup window | I29: High | J29: percent of cohort should be displayed w Grade Level = "MS" percent of cohort w Grade Level = "HS" under the Cohort.
B30: Rakesh Kumar Singh | C30: 41703 | D30: Cohort | E30: TC-TFACMM-1.0.37 | F30: verify % Person of Color % Low income background on group popup window | G30: Open the group popup window. 2) Verify % Person of Color and % Low income background on group popup window | I30: High | J30: % Person of Color % Low income background
B31: Rakesh Kumar Singh | C31: 41703 | D31: Cohort | E31: TC-TFACMM-1.0.38 | F31: verify Feeder pattern HS | G31: Open the group popup window. 2) Verify Feeder pattern HS on group popup window | I31: High | J31: Feeder pattern HS should be displayed under the group detail pop up
B32: Rakesh Kumar Singh | C32: 41710 | D32: Cohort | E32: TC-TFACMM-1.0.39 | F32: Test the application response when User Move the MTLD different cohorts | G32: 1. Enter a valid "TeachForAmerica ID" in the field 2. Enter a valid password in the field 3. Click on "Login" button 4. Criteria Select Page should be displayed. 5.selects value for each criterion and enters in any additionally required values (e.g.#schools/MTLD) and clicks 6.Click the check box(unhired CMs and CM-MTLD pairing? ) and press the Make my matches button 7. CM Cohorts page should be displayed. 8. Move the MTLD different cohorts | I32: High | J32: users should be able to Move the MTLD different cohorts
B33: Rakesh Kumar Singh | C33: 41710 | D33: Cohort | E33: TC-TFACMM-1.0.40 | F33: Test the application response when User click on MTLD Pop up | G33: 1. Enter a valid "TeachForAmerica ID" in the field 2. Enter a valid password in the field 3. Click on "Login" button 4. Criteria Select Page should be displayed. 5.Select Criteria and provide Specific prioritize 6.Click the check box(CM-MTLDpairing?) and press the Make my matches button 7. CM Cohorts page should be displayed. 8. click on MTLD POP UP | I33: Medium | J33: Below information should be displayed under the MTLD pop-up 1) Tenure in role 2) Alum? 3) Corps Region 4) Subject Taught 5) CMO Affiliation 6) Person of color? 7) Low income background? 8) Neighborhood
B34: Rakesh Kumar Singh | C34: 41710 | D34: Cohort | E34: TC-TFACMM-1.0.41 | F34: Test the application response when User click on group under the cohorts | G34: 1. Enter a valid "TeachForAmerica ID" in the field 2. Enter a valid password in the field 3. Click on "Login" button 4. Criteria Select Page should be displayed. 5.Select Criteria and provide Specific prioritize 6.Click the check box(CM-MTLDpairing?) and press the Make my matches button 7. CM Cohorts page should be displayed. 8. click on any group under the cohorts | I34: Medium | J34: group is expanded in the left side and all CMs displayed in the list selected group is highlighted in the cohorts.
B35: Rakesh Kumar Singh | C35: 41724 | D35: Cohort | E35: TC-TFACMM-1.0.42 | F35: Verify when When the Red indicator light is on for CMs , can we have a ‘mouse over’ that displays text “Not fit for group” | G35: 1. Enter a valid "TeachForAmerica ID" in the field 2. Enter a valid password in the field 3. Click on "Login" button 4. Criteria Select Page should be displayed. 5.selects value for each criterion and enters in any additionally required values (e.g.#schools/MTLD) and clicks 6.Click the check box(unhired CMs and CM-MTLD pairing? ) and press the Make my matches button 7. CM Cohorts page should be displayed. | J35: When the Red indicator light is on for CMs , can we have a ‘mouse over’ that displays text “Not fit for group ”displayed. Note: Verify the Red indicator light calculation
B36: Rakesh Kumar Singh | C36: 41724 | D36: Cohort | E36: TC-TFACMM-1.0.43 | F36: Verify CMs detail pop-up when click on the CMs | G36: 1. Enter a valid "TeachForAmerica ID" in the field 2. Enter a valid password in the field 3. Click on "Login" button 4. Criteria Select Page should be displayed. 5.selects value for each criterion and enters in any additionally required values (e.g.#schools/MTLD) and clicks 6.Click the check box(unhired CMs and CM-MTLD pairing? ) and press the Make my matches button 7. CM Cohorts page should be displayed. 8. click on CMs pop up | J36: CMs pop up should be displayed with following • Corps Year • Grade Level • Primary Subject • Specialty Area (subject modifier) • School Name • Neighborhood
B37: Rakesh Kumar Singh | C37: 41724 | D37: Cohort | E37: TC-TFACMM-1.0.44 | F37: Check whether deleting a particular CMs record does not affect the existing records. | G37: 1. Enter a valid "TeachForAmerica ID" in the field 2. Enter a valid password in the field 3. Click on "Login" button 4. Criteria Select Page should be displayed. 5.selects value for each criterion and enters in any additionally required values (e.g.#schools/MTLD) and clicks 6.Click the check box(unhired CMs and CM-MTLD pairing? ) and press the Make my matches button 7. CM Cohorts page should be displayed. 8. click on CMs pop up 9) Click on Cross image icon present on panel. | J37: Application should removed the record from the panel and move it to pool.
B38: Rakesh Kumar Singh | C38: 41704 | D38: Cohort | E38: TC-TFACMM-1.0.45 | F38: Scroll-bar need to be available to see the entire Cohorts. | G38: 1.Access the Application. 2.Logged in with Valid TFA ID and valid password. 3.click on Login button. 4.select some Criteria and prioritize. 5.click on Make my matches button. 6. Scroll bar displayed. | I38: High | J38: Scroll bar should work as expected
B39: Rakesh Kumar Singh | C39: 41710 | D39: Cohort | E39: TC-TFACMM-1.0.46 | F39: Test the application response when User filter the unhired CMs | G39: 1. Enter a valid "TeachForAmerica ID" in the field 2. Enter a valid password in the field 3. Click on "Login" button 4. Criteria Select Page should be displayed. 5.selects value for each criterion and enters in any additionally required values (e.g.#schools/MTLD) and clicks 6.Click the check box(unhired CMs and CM-MTLD pairing? ) and press the Make my matches button 7. CM Cohorts page should be displayed. 8.users should be able to filter in Drop down unhired CMs | I39: High | J39: users should be able to filter the unhired CMs as per the Filter values: ● eligible for HS ● eligible for MS ● eligible for Elementary ● eligible for ECE ● eligible for STEM ● eligible for SPED ● Corps year (1CM or 2CM) First Name Last Name Hiring stage select any one values under the drop down, selected values displayed in the unhired list
B40: Rakesh Kumar Singh | C40: 41710 | D40: Cohort | E40: TC-TFACMM-1.0.47 | F40: Verify the content on drop down for corps members. | G40: 1. Enter a valid "TeachForAmerica ID" in the field 2. Enter a valid password in the field 3. Click on "Login" button 4. Criteria Select Page should be displayed. 5.selects value for each criterion and enters in any additionally required values (e.g.#schools/MTLD) and clicks 6.Click the check box(unhired CMs and CM-MTLD pairing? ) and press the Make my matches button 7. CM Cohorts page should be displayed. 8.users should be able to filter in Drop down unhired CMs | I40: High | J40: drop down box value 1) CMs count 2) MTLD Count 3) Unhired count should be displayed under the corps member droop down
B41: Rakesh Kumar Singh | C41: 41710 | D41: Cohort | E41: TC-TFACMM-1.0.48 | F41: Verify Cms 'Move to group ' functionality | G41: 1. Enter a valid "TeachForAmerica ID" in the field 2. Enter a valid password in the field 3. Click on "Login" button 4. Criteria Select Page should be displayed. 5.selects value for each criterion and enters in any additionally required values (e.g.#schools/MTLD) and clicks 6.Click the check box(unhired CMs and CM-MTLD pairing? ) and press the Make my matches button 7. CM Cohorts page should be displayed. 8. Click on Arrow image present on Corps members grid | I41: High | J41: Selected CMs should be move to current cohort.
B42: Rakesh Kumar Singh | C42: 41703 | D42: Cohort | E42: TC-TFACMM-1.0.49 | F42: verify Rematch button on the right corner in the cohort window | G42: 1. Enter a valid "TeachForAmerica ID" in the field 2. Enter a valid password in the field 3. Click on "Login" button 4. Criteria Select Page should be displayed. 5.selects value for each criterion and enters in any additionally required values (e.g.#schools/MTLD) and clicks 6.Click the check box(unhired CMs and CM-MTLD pairing? ) and press the Make my matches button 7. CM Cohorts page should be displayed. 8. click on Rematch button. 9.Navigate to Criteria page and select the specific criteria and prioritize click on make my match button . | I42: High | J42: as per the selected result should be displayed in the cohort page.
...

Sheet TC_Map
F2: Diaspark Inc. | H2: =TC_Common!H2 -> DP-TFACMM-TCD-V1.1
B3: Test Cases
B4: Document Reference | C4: RequirementsDetailedUseCases | F4: Environment | G4: FF,IE8,9,Google Chrome
B5: Test Type | C5: Functional | F5: Brief Description | G5: System testing including functional,compatablity ,UI Testing of MTLD-CM
B6: Project Name | C6: MTLD-CM Matching Tool | F6: Reviewed By | G6: Alok Tapdiya,Arun Rathore
B7: Module Name | C7: TC_Map | F7: Approved By | G7: Alok Tapdiya
B9: Created By | C9: Created on | D9: Requirement/Task ID | E9: Test case ID | F9: Test Case Objective | G9: Test Steps /Procedure | H9: Test Data (Optional) | I9: Importance /Priority | J9: Expected Result | K9: Actual Result (Iteration 1) | L9: Status (Iteration 1) | M9: Bug ID (Iteration 1) | N9: Execution Date (Iteration 1) | O9: Executed By (Iteration 1) | P9: Comments (Iteration 1) | Q9: Actual Result (Iteration 2) | R9: Status (Iteration 2) | S9: Bug ID (Iteration 2) | T9: Execution Date (Iteration 2) | U9: Executed By (Iteration 2) | V9: Comments (Iteration 2) | W9: Actual Result (Iteration 3) | X9: Status (Iteration 3) | Y9: Bug ID (Iteration 3) | Z9: Execution Date (Iteration 3) | AA9: Executed By (Iteration 3) | AB9: Comments (Iteration 3) | AC9: Actual Result (Iteration 4) | AD9: Status (Iteration 4) | AE9: Bug ID (Iteration 4) | AF9: Execution Date (Iteration 4) | AG9: Executed By (Iteration 4) | AH9: Comments (Iteration 4) | AI9: Actual Result (Iteration 5) | AJ9: Status (Iteration 5) | AK9: Bug ID (Iteration 5) | AL9: Execution Date (Iteration 5) | AM9: Executed By (Iteration 5) | AN9: Comments (Iteration 5) | AO9: Actual Result (Iteration 6) | AP9: Status (Iteration 6) | AQ9: Bug ID (Iteration 6) | AR9: Execution Date (Iteration 6) | AS9: Executed By (Iteration 6) | AT9: Comments (Iteration 6) | AU9: Actual Result (Iteration 7) | AV9: Status (Iteration 7) | AW9: Bug ID (Iteration 7) | AX9: Execution Date (Iteration 7) | AY9: Executed By (Iteration 7) | AZ9: Comments (Iteration 7) | BA9: Actual Result (Iteration 8) | BB9: Status (Iteration 8) | BC9: Bug ID (Iteration 8) | BD9: Execution Date (Iteration 8) | BE9: Executed By (Iteration 8) | BF9: Comments (Iteration 8) | BG9: Actual Result (Iteration 9) | BH9: Status (Iteration 9) | BI9: Bug ID (Iteration 9) | BJ9: Execution Date (Iteration 9) | BK9: Executed By (Iteration 9) | BL9: Comments (Iteration 9) | BM9: Actual Result (Iteration 10) | BN9: Status (Iteration 10) | BO9: Bug ID (Iteration 10) | BP9: Execution Date (Iteration 10) | BQ9: Executed By (Iteration 10) | BR9: Comments (Iteration 10)
B10: Rakesh Kumar Singh | C10: 41705 | D10: Map-School address | E10: TC-TFACMM-1.0.65 | F10: Verify the school address displayed in the Map | G10: 1.Access the Application. 2.Logged in with Valid TFA ID and valid password. 3.click on Login button. 4.select Criteria and click on Make my matches button. 5. cohort page should be displayed | I10: High | J10: School Address should be displayed with Combination of "Address 1", "City", State", Zip" | L10: <Select> | R10: <Select> | X10: <Select> | AD10: <Select> | AJ10: <Select> | AP10: <Select> | AV10: <Select> | BB10: <Select> | BH10: <Select> | BN10: <Select>
B11: Rakesh Kumar Singh | C11: 41705 | D11: Map-#CMs at school | E11: TC-TFACMM-1.0.66 | F11: Verify the #CMs at school displayed in the Map | G11: 1.Access the Application. 2.Logged in with Valid TFA ID and valid password. 3.click on Login button. 4.select Criteria . 5.click on Make my matches button. | I11: High | J11: cops member count should be displayed under the map. | L11: <Select> | R11: <Select> | X11: <Select> | AD11: <Select> | AJ11: <Select> | AP11: <Select> | AV11: <Select> | BB11: <Select> | BH11: <Select> | BN11: <Select>
B12: Rakesh Kumar Singh | C12: 41705 | D12: Map-No of MTLD in the school | E12: TC-TFACMM-1.0.67 | F12: Verify the #MTLD at The school displayed in the Map | G12: 1.Access the Application. 2.Logged in with Valid TFA ID and valid password. 3.click on Login button. 4.select Criteria . 5.click on Make my matches button. | I12: High | J12: MTLD member count should be displayed under the school in map. | L12: <Select> | R12: <Select> | X12: <Select> | AD12: <Select> | AJ12: <Select> | AP12: <Select> | AV12: <Select> | BB12: <Select> | BH12: <Select> | BN12: <Select>
B13: Rakesh Kumar Singh | C13: 41705 | D13: Map-color system | E13: TC-TFACMM-1.0.68 | F13: Verify The color system should be Displayed based on the MTLD | G13: 1.Access the Application. 2.Logged in with Valid TFA ID and valid password. 3.click on Login button. 4.select Criteria . 5.click on Make my matches button. | I13: High | J13: The color system should be displayed based on the MTLD | L13: <Select> | R13: <Select> | X13: <Select> | AD13: <Select> | AJ13: <Select> | AP13: <Select> | AV13: <Select> | BB13: <Select> | BH13: <Select> | BN13: <Select>
B14: Rakesh Kumar Singh | C14: 41705 | D14: Map-Single Location | E14: TC-TFACMM-1.0.69 | F14: Click on a single location | G14: 1.Access the Application. 2.Logged in with Valid TFA ID and valid password. 3.click on Login button. 4.select Criteria . 5.click on Make my matches button. | I14: High | J14: Map centers on that location and an information popup displays reviews and address, and link to get directions | L14: <Select> | R14: <Select> | X14: <Select> | AD14: <Select> | AJ14: <Select> | AP14: <Select> | AV14: <Select> | BB14: <Select> | BH14: <Select> | BN14: <Select>
B15: Rakesh Kumar Singh | C15: 41716 | D15: Cross-Browser | E15: TC-TFACMM-1.0.70 | F15: To Check that Test Cases From TC-1 To TC-5 should be Pass | G15: 1. Execute Test Case from TC-1 to TC-5 on different browser | H15: 1.FF 2.IE 3.Google Chrome 4.Safari | I15: High | J15: All Test Case from TC-1 to TC-5 should be pass. | L15: <Select> | R15: <Select> | X15: <Select> | AD15: <Select> | AJ15: <Select> | AP15: <Select> | AV15: <Select> | BB15: <Select> | BH15: <Select> | BN15: <Select>
I16: <Select> | L16: <Select> | R16: <Select> | X16: <Select> | AD16: <Select> | AJ16: <Select> | AP16: <Select> | AV16: <Select> | BB16: <Select> | BH16: <Select> | BN16: <Select>
I17: <Select> | L17: <Select> | R17: <Select> | X17: <Select> | AD17: <Select> | AJ17: <Select> | AP17: <Select> | AV17: <Select> | BB17: <Select> | BH17: <Select> | BN17: <Select>
I18: <Select> | L18: <Select> | R18: <Select> | X18: <Select> | AD18: <Select> | AJ18: <Select> | AP18: <Select> | AV18: <Select> | BB18: <Select> | BH18: <Select> | BN18: <Select>

Sheet  Amendment History
B2: Document Creation Details
B3: Author | C3: Rakesh Kushwah/Rakesh singh | D3: Approved By | E3: Alok Tapdiya
B4: Reviewed By | C4: Rakesh Kushwah/Alok Tapdiya | D4: Document Creation Date | E4: 41703
B6: Amendment History
B7: Version | C7: Date | D7: Addition/Modification | E7: Revised By | F7: Reviewed By
B8: V1.0 | C8: 41703 | D8: Document Creation | E8: Rakesh singh | F8: Rakesh Kushwa
B9: V1.1 | C9: 39546 | D9: Modification :- 1) Reformat the Test Case sheet 2) Added the formula for the test case 3) Remove the test case for login window | E9: Rakesh singh | F9: Rakesh Kushwah
